Workbook

Sheet Parameters
A1: WFH Perturbation Framework — Reference Parameters
A2: This sheet contains all baseline WFH rates, structural upper bounds, and computed joint propensity matrices.
A4: Section 1: Baseline WFH Rates and Upper Bounds by Education
B5: Education Level | C5: Baseline Rate (wₑ) | D5: Upper Bound (uₑ) | E5: Source
B6: Less than HS | C6: 0.035 | D6: 0.098 | E6: CPS Q1 2024 / Dingel-Neiman 2020
B7: HS Diploma | C7: 0.085 | D7: 0.183 | E7: CPS Q1 2024 / Dingel-Neiman 2020
B8: Some College/Assoc. | C8: 0.183 | D8: 0.317 | E8: CPS Q1 2024 / Dingel-Neiman 2020
B9: Bachelor's | C9: 0.384 | D9: 0.556 | E9: CPS Q1 2024 / Dingel-Neiman 2020
B10: Advanced | C10: 0.436 | D10: 0.674 | E10: CPS Q1 2024 / Dingel-Neiman 2020
A12: Section 2: Baseline WFH Rates and Upper Bounds by Industry
A13: LODES | B13: Industry Sector | C13: Baseline Rate (wₒ) | D13: Upper Bound (uₒ) | E13: Source
A14: CNS01 | B14: Agriculture, Forestry, Fishing | C14: 0.123 | D14: 0.2 | E14: CPS Aug 2024 / Dingel-Neiman 2020
A15: CNS02 | B15: Mining, Quarrying, Oil/Gas | C15: 0.162 | D15: 0.25 | E15: CPS Aug 2024 / Dingel-Neiman 2020
A16: CNS03 | B16: Utilities | C16: 0.277 | D16: 0.37 | E16: CPS Aug 2024 / Dingel-Neiman 2020
A17: CNS04 | B17: Construction | C17: 0.089 | D17: 0.19 | E17: CPS Aug 2024 / Dingel-Neiman 2020
A18: CNS05 | B18: Manufacturing | C18: 0.196 | D18: 0.22 | E18: CPS Aug 2024 / Dingel-Neiman 2020
A19: CNS06 | B19: Wholesale Trade | C19: 0.234 | D19: 0.52 | E19: CPS Aug 2024 / Dingel-Neiman 2020
A20: CNS07 | B20: Retail Trade | C20: 0.11 | D20: 0.14 | E20: CPS Aug 2024 / Dingel-Neiman 2020
A21: CNS08 | B21: Transportation & Warehousing | C21: 0.08 | D21: 0.19 | E21: CPS Aug 2024 / Dingel-Neiman 2020
A22: CNS09 | B22: Information | C22: 0.5 | D22: 0.72 | E22: CPS Aug 2024 / Dingel-Neiman 2020
A23: CNS10 | B23: Finance & Insurance | C23: 0.595 | D23: 0.76 | E23: CPS Aug 2024 / Dingel-Neiman 2020
A24: CNS11 | B24: Real Estate & Rental/Leasing | C24: 0.421 | D24: 0.6 | E24: CPS Aug 2024 / Dingel-Neiman 2020
A25: CNS12 | B25: Professional, Scientific, Tech | C25: 0.597 | D25: 0.8 | E25: CPS Aug 2024 / Dingel-Neiman 2020
... A33: CNS20 | B33: Public Administration | C33: 0.271 | D33: 0.41 | E33: CPS Aug 2024 / Dingel-Neiman 2020
A35: Section 3: Joint Baseline WFH Propensity wₑₒ = 1 − (1−wₑ)(1−wₒ)
A36: Each cell combines education and industry WFH rates as independent contributors. Higher values = higher baseline remote work probability.
A37: LODES | B37: Industry | C37: Less than HS | D37: HS Diploma | E37: Some College/Assoc. | F37: Bachelor's | G37: Advanced
A38: CNS01 | B38: Agriculture, Forestry, Fishing | C38: =1-(1-C6)*(1-C14) | D38: =1-(1-C7)*(1-C14) | E38: =1-(1-C8)*(1-C14) | F38: =1-(1-C9)*(1-C14) | G38: =1-(1-C10)*(1-C14)
A39: CNS02 | B39: Mining, Quarrying, Oil/Gas | C39: =1-(1-C6)*(1-C15) | D39: =1-(1-C7)*(1-C15) | E39: =1-(1-C8)*(1-C15) | F39: =1-(1-C9)*(1-C15) | G39: =1-(1-C10)*(1-C15)
A40: CNS03 | B40: Utilities | C40: =1-(1-C6)*(1-C16) | D40: =1-(1-C7)*(1-C16) | E40: =1-(1-C8)*(1-C16) | F40: =1-(1-C9)*(1-C16) | G40: =1-(1-C10)*(1-C16)
A41: CNS04 | B41: Construction | C41: =1-(1-C6)*(1-C17) | D41: =1-(1-C7)*(1-C17) | E41: =1-(1-C8)*(1-C17) | F41: =1-(1-C9)*(1-C17) | G41: =1-(1-C10)*(1-C17)
A42: CNS05 | B42: Manufacturing | C42: =1-(1-C6)*(1-C18) | D42: =1-(1-C7)*(1-C18) | E42: =1-(1-C8)*(1-C18) | F42: =1-(1-C9)*(1-C18) | G42: =1-(1-C10)*(1-C18)
A43: CNS06 | B43: Wholesale Trade | C43: =1-(1-C6)*(1-C19) | D43: =1-(1-C7)*(1-C19) | E43: =1-(1-C8)*(1-C19) | F43: =1-(1-C9)*(1-C19) | G43: =1-(1-C10)*(1-C19)
A44: CNS07 | B44: Retail Trade | C44: =1-(1-C6)*(1-C20) | D44: =1-(1-C7)*(1-C20) | E44: =1-(1-C8)*(1-C20) | F44: =1-(1-C9)*(1-C20) | G44: =1-(1-C10)*(1-C20)
A45: CNS08 | B45: Transportation & Warehousing | C45: =1-(1-C6)*(1-C21) | D45: =1-(1-C7)*(1-C21) | E45: =1-(1-C8)*(1-C21) | F45: =1-(1-C9)*(1-C21) | G45: =1-(1-C10)*(1-C21)
A46: CNS09 | B46: Information | C46: =1-(1-C6)*(1-C22) | D46: =1-(1-C7)*(1-C22) | E46: =1-(1-C8)*(1-C22) | F46: =1-(1-C9)*(1-C22) | G46: =1-(1-C10)*(1-C22)
A47: CNS10 | B47: Finance & Insurance | C47: =1-(1-C6)*(1-C23) | D47: =1-(1-C7)*(1-C23) | E47: =1-(1-C8)*(1-C23) | F47: =1-(1-C9)*(1-C23) | G47: =1-(1-C10)*(1-C23)
A48: CNS11 | B48: Real Estate & Rental/Leasing | C48: =1-(1-C6)*(1-C24) | D48: =1-(1-C7)*(1-C24) | E48: =1-(1-C8)*(1-C24) | F48: =1-(1-C9)*(1-C24) | G48: =1-(1-C10)*(1-C24)
A49: CNS12 | B49: Professional, Scientific, Tech | C49: =1-(1-C6)*(1-C25) | D49: =1-(1-C7)*(1-C25) | E49: =1-(1-C8)*(1-C25) | F49: =1-(1-C9)*(1-C25) | G49: =1-(1-C10)*(1-C25)
A50: CNS13 | B50: Management of Companies | C50: =1-(1-C6)*(1-C26) | D50: =1-(1-C7)*(1-C26) | E50: =1-(1-C8)*(1-C26) | F50: =1-(1-C9)*(1-C26) | G50: =1-(1-C10)*(1-C26)
...

Sheet Ex1 NYC Intra-City
A1: Example 1: Two Census Tracts Within New York City
A2: Tract 7, Financial District (workplace: finance/professional) vs. Tract 184, East Harlem (workplace: healthcare/education)
A4: Scenario Parameter
B5: α (proportional WFH scaling factor) | C5: 0.25
B6: Δwₑₒ = α · wₑₒ → A positive α means WFH increases proportionally across all segments.
A8: Step 1: Demographic Inputs for the Two Tracts
C9: Zone i | D9: Zone j
B10: Tract Name | C10: Tract 7, Financial Dist. | D10: Tract 184, East Harlem
B11: FIPS Code | C11: 36061000700 | D11: 36061018400
A13: Education Shares at Residence (Eᵣₑ) — from ACS Table B15003
C14: Less than HS | D14: HS Diploma | E14: Some College/Assoc. | F14: Bachelor's | G14: Advanced | H14: Total
B15: Zone i: Tract 7, Financial Dist. | C15: 0.016427 | D15: 0.039343 | E15: 0.080618 | F15: 0.496825 | G15: 0.366786 | H15: =SUM(C15:G15)
B16: Zone j: Tract 184, East Harlem | C16: 0.178913 | D16: 0.196914 | E16: 0.276267 | F16: 0.223549 | G16: 0.124357 | H16: =SUM(C16:G16)
A18: Industry Shares at Workplace (Oₛₒ) — from LODES WAC files
A19: LODES | B19: Industry Sector | C19: Zone i (workplace) | D19: Zone j (workplace)
A20: CNS01 | B20: Agriculture, Forestry, Fishing | C20: 0 | D20: 0
A21: CNS02 | B21: Mining, Quarrying, Oil/Gas | C21: 7.7e-05 | D21: 0
A22: CNS03 | B22: Utilities | C22: 3.9e-05 | D22: 0
A23: CNS04 | B23: Construction | C23: 0.020311 | D23: 0.028777
A24: CNS05 | B24: Manufacturing | C24: 0.00114 | D24: 0.005139
A25: CNS06 | B25: Wholesale Trade | C25: 0.032544 | D25: 0.001028
A26: CNS07 | B26: Retail Trade | C26: 0.068643 | D26: 0.088386
A27: CNS08 | B27: Transportation & Warehousing | C27: 0.013991 | D27: 0
A28: CNS09 | B28: Information | C28: 0.034476 | D28: 0.003083
A29: CNS10 | B29: Finance & Insurance | C29: 0.197696 | D29: 0.005139
A30: CNS11 | B30: Real Estate & Rental/Leasing | C30: 0.012445 | D30: 0.077081
A31: CNS12 | B31: Professional, Scientific, Tech | C31: 0.232907 | D31: 0.017472
... A39: CNS20 | B39: Public Administration | C39: 0.045066 | D39: 0.121274
B40: Total | C40: =SUM(C20:C39) | D40: =SUM(D20:D39)
A42: LODES Commute Counts and Deep Gravity Baseline Flow
B43: L_ij (workers with residence r=i, workplace s=j) | C43: 0
B44: L_ji (workers with residence r=j, workplace s=i) | C44: 23
B45: T_ij (Deep Gravity baseline flow, dummy) | C45: 2200
A47: Step 2: Bounded Perturbation Deltas Δwₑₒ = max(−wₑₒ, min(α·wₑₒ, uₑₒ−wₑₒ))
A48: Change in WFH rate for each segment, bounded by structural feasibility. Positive = more WFH; negative = less WFH.
A49: LODES | B49: Industry | C49: Less than HS | D49: HS Diploma | E49: Some College/Assoc. | F49: Bachelor's | G49: Advanced
A50: CNS01 | B50: Agriculture, Forestry, Fishing | C50: =MAX(-Parameters!C38,MIN($C$5*Parameters!C38,Parameters!C62-Parameters!C38)) | D50: =MAX(-Parameters!D38,MIN($C$5*Parameters!D38,Parameters!D62-Parameters!D38)) | E50: =MAX(-Parameters!E38,MIN($C$5*Parameters!E38,Parameters!E62-Parameters!E38)) | F50: =MAX(-Parameters!F38,MIN($C$5*Parameters!F38,Parameters!F62-Parameters!F38)) | G50: =MAX(-Parameters!G38,MIN($C$5*Parameters!G38,Parameters!G62-Parameters!G38))
A51: CNS02 | B51: Mining, Quarrying, Oil/Gas | C51: =MAX(-Parameters!C39,MIN($C$5*Parameters!C39,Parameters!C63-Parameters!C39)) | D51: =MAX(-Parameters!D39,MIN($C$5*Parameters!D39,Parameters!D63-Parameters!D39)) | E51: =MAX(-Parameters!E39,MIN($C$5*Parameters!E39,Parameters!E63-Parameters!E39)) | F51: =MAX(-Parameters!F39,MIN($C$5*Parameters!F39,Parameters!F63-Parameters!F39)) | G51: =MAX(-Parameters!G39,MIN($C$5*Parameters!G39,Parameters!G63-Parameters!G39))
A52: CNS03 | B52: Utilities | C52: =MAX(-Parameters!C40,MIN($C$5*Parameters!C40,Parameters!C64-Parameters!C40)) | D52: =MAX(-Parameters!D40,MIN($C$5*Parameters!D40,Parameters!D64-Parameters!D40)) | E52: =MAX(-Parameters!E40,MIN($C$5*Parameters!E40,Parameters!E64-Parameters!E40)) | F52: =MAX(-Parameters!F40,MIN($C$5*Parameters!F40,Parameters!F64-Parameters!F40)) | G52: =MAX(-Parameters!G40,MIN($C$5*Parameters!G40,Parameters!G64-Parameters!G40))
A53: CNS04 | B53: Construction | C53: =MAX(-Parameters!C41,MIN($C$5*Parameters!C41,Parameters!C65-Parameters!C41)) | D53: =MAX(-Parameters!D41,MIN($C$5*Parameters!D41,Parameters!D65-Parameters!D41)) | E53: =MAX(-Parameters!E41,MIN($C$5*Parameters!E41,Parameters!E65-Parameters!E41)) | F53: =MAX(-Parameters!F41,MIN($C$5*Parameters!F41,Parameters!F65-Parameters!F41)) | G53: =MAX(-Parameters!G41,MIN($C$5*Parameters!G41,Parameters!G65-Parameters!G41))
...

Sheet Ex2 NYC Metro
A1: Example 2: Two Census Tracts in the NYC Metro Area
A2: Tract 50, Bergen County NJ (suburban bedroom community) vs. Tract 100, Midtown Manhattan (office district)
A4: Scenario Parameter
B5: α (proportional WFH scaling factor) | C5: 0.25
B6: Δwₑₒ = α · wₑₒ → A positive α means WFH increases proportionally across all segments.
A8: Step 1: Demographic Inputs for the Two Tracts
C9: Zone i | D9: Zone j
B10: Tract Name | C10: Tract 50, Bergen Co. NJ | D10: Tract 100, Midtown Manhattan
B11: FIPS Code | C11: 34003005000 | D11: 36061010000
A13: Education Shares at Residence (Eᵣₑ) — from ACS Table B15003
C14: Less than HS | D14: HS Diploma | E14: Some College/Assoc. | F14: Bachelor's | G14: Advanced | H14: Total
B15: Zone i: Tract 50, Bergen Co. NJ | C15: 0.05218 | D15: 0.392139 | E15: 0.247572 | F15: 0.185905 | G15: 0.122205 | H15: =SUM(C15:G15)
B16: Zone j: Tract 100, Midtown Manhat | C16: 0.006887 | D16: 0.097107 | E16: 0.013774 | F16: 0.469008 | G16: 0.413223 | H16: =SUM(C16:G16)
A18: Industry Shares at Workplace (Oₛₒ) — from LODES WAC files
A19: LODES | B19: Industry Sector | C19: Zone i (workplace) | D19: Zone j (workplace)
A20: CNS01 | B20: Agriculture, Forestry, Fishing | C20: 0.000163 | D20: 0
A21: CNS02 | B21: Mining, Quarrying, Oil/Gas | C21: 0 | D21: 0
A22: CNS03 | B22: Utilities | C22: 0.000894 | D22: 0
A23: CNS04 | B23: Construction | C23: 0.060941 | D23: 0.006832
A24: CNS05 | B24: Manufacturing | C24: 0.231494 | D24: 0.000277
A25: CNS06 | B25: Wholesale Trade | C25: 0.221662 | D25: 0.009764
A26: CNS07 | B26: Retail Trade | C26: 0.05956 | D26: 0.006472
A27: CNS08 | B27: Transportation & Warehousing | C27: 0.15609 | D27: 0.000885
A28: CNS09 | B28: Information | C28: 0.007394 | D28: 0.039359
A29: CNS10 | B29: Finance & Insurance | C29: 0.00585 | D29: 0.414643
A30: CNS11 | B30: Real Estate & Rental/Leasing | C30: 0.044528 | D30: 0.042319
A31: CNS12 | B31: Professional, Scientific, Tech | C31: 0.04859 | D31: 0.268075
... A39: CNS20 | B39: Public Administration | C39: 0.011457 | D39: 0.011617
B40: Total | C40: =SUM(C20:C39) | D40: =SUM(D20:D39)
A42: LODES Commute Counts and Deep Gravity Baseline Flow
B43: L_ij (workers with residence r=i, workplace s=j) | C43: 0
B44: L_ji (workers with residence r=j, workplace s=i) | C44: 0
B45: T_ij (Deep Gravity baseline flow, dummy) | C45: 2800
A47: Step 2: Bounded Perturbation Deltas Δwₑₒ = max(−wₑₒ, min(α·wₑₒ, uₑₒ−wₑₒ))
A48: Change in WFH rate for each segment, bounded by structural feasibility. Positive = more WFH; negative = less WFH.
A49: LODES | B49: Industry | C49: Less than HS | D49: HS Diploma | E49: Some College/Assoc. | F49: Bachelor's | G49: Advanced
A50: CNS01 | B50: Agriculture, Forestry, Fishing | C50: =MAX(-Parameters!C38,MIN($C$5*Parameters!C38,Parameters!C62-Parameters!C38)) | D50: =MAX(-Parameters!D38,MIN($C$5*Parameters!D38,Parameters!D62-Parameters!D38)) | E50: =MAX(-Parameters!E38,MIN($C$5*Parameters!E38,Parameters!E62-Parameters!E38)) | F50: =MAX(-Parameters!F38,MIN($C$5*Parameters!F38,Parameters!F62-Parameters!F38)) | G50: =MAX(-Parameters!G38,MIN($C$5*Parameters!G38,Parameters!G62-Parameters!G38))
A51: CNS02 | B51: Mining, Quarrying, Oil/Gas | C51: =MAX(-Parameters!C39,MIN($C$5*Parameters!C39,Parameters!C63-Parameters!C39)) | D51: =MAX(-Parameters!D39,MIN($C$5*Parameters!D39,Parameters!D63-Parameters!D39)) | E51: =MAX(-Parameters!E39,MIN($C$5*Parameters!E39,Parameters!E63-Parameters!E39)) | F51: =MAX(-Parameters!F39,MIN($C$5*Parameters!F39,Parameters!F63-Parameters!F39)) | G51: =MAX(-Parameters!G39,MIN($C$5*Parameters!G39,Parameters!G63-Parameters!G39))
A52: CNS03 | B52: Utilities | C52: =MAX(-Parameters!C40,MIN($C$5*Parameters!C40,Parameters!C64-Parameters!C40)) | D52: =MAX(-Parameters!D40,MIN($C$5*Parameters!D40,Parameters!D64-Parameters!D40)) | E52: =MAX(-Parameters!E40,MIN($C$5*Parameters!E40,Parameters!E64-Parameters!E40)) | F52: =MAX(-Parameters!F40,MIN($C$5*Parameters!F40,Parameters!F64-Parameters!F40)) | G52: =MAX(-Parameters!G40,MIN($C$5*Parameters!G40,Parameters!G64-Parameters!G40))
A53: CNS04 | B53: Construction | C53: =MAX(-Parameters!C41,MIN($C$5*Parameters!C41,Parameters!C65-Parameters!C41)) | D53: =MAX(-Parameters!D41,MIN($C$5*Parameters!D41,Parameters!D65-Parameters!D41)) | E53: =MAX(-Parameters!E41,MIN($C$5*Parameters!E41,Parameters!E65-Parameters!E41)) | F53: =MAX(-Parameters!F41,MIN($C$5*Parameters!F41,Parameters!F65-Parameters!F41)) | G53: =MAX(-Parameters!G41,MIN($C$5*Parameters!G41,Parameters!G65-Parameters!G41))
...

Sheet Ex3 Austin TX
A1: Example 3: Two Census Tracts in Austin, Texas
A2: Tract 11.01, Downtown Austin (tech/govt/professional) vs. Tract 24.22, Suburban Austin (education/accommodation)
A4: Scenario Parameter
B5: α (proportional WFH scaling factor) | C5: 0.25
B6: Δwₑₒ = α · wₑₒ → A positive α means WFH increases proportionally across all segments.
A8: Step 1: Demographic Inputs for the Two Tracts
C9: Zone i | D9: Zone j
B10: Tract Name | C10: Tract 11.01, Downtown Austin | D10: Tract 24.22, Suburban Austin
B11: FIPS Code | C11: 48453001101 | D11: 48453002422
A13: Education Shares at Residence (Eᵣₑ) — from ACS Table B15003
C14: Less than HS | D14: HS Diploma | E14: Some College/Assoc. | F14: Bachelor's | G14: Advanced | H14: Total
B15: Zone i: Tract 11.01, Downtown Aus | C15: 0.062756 | D15: 0.186221 | E15: 0.07708 | F15: 0.401774 | G15: 0.272169 | H15: =SUM(C15:G15)
B16: Zone j: Tract 24.22, Suburban Aus | C16: 0.150966 | D16: 0.136357 | E16: 0.234211 | F16: 0.370263 | G16: 0.108203 | H16: =SUM(C16:G16)
A18: Industry Shares at Workplace (Oₛₒ) — from LODES WAC files
A19: LODES | B19: Industry Sector | C19: Zone i (workplace) | D19: Zone j (workplace)
A20: CNS01 | B20: Agriculture, Forestry, Fishing | C20: 0.000204 | D20: 0
A21: CNS02 | B21: Mining, Quarrying, Oil/Gas | C21: 0.000957 | D21: 0
A22: CNS03 | B22: Utilities | C22: 0.021862 | D22: 0
A23: CNS04 | B23: Construction | C23: 0.012274 | D23: 0.093318
A24: CNS05 | B24: Manufacturing | C24: 0.022371 | D24: 0.10023
A25: CNS06 | B25: Wholesale Trade | C25: 0.021638 | D25: 0.033986
A26: CNS07 | B26: Retail Trade | C26: 0.042258 | D26: 0.084677
A27: CNS08 | B27: Transportation & Warehousing | C27: 0.00631 | D27: 0.044355
A28: CNS09 | B28: Information | C28: 0.064934 | D28: 0.004608
A29: CNS10 | B29: Finance & Insurance | C29: 0.060435 | D29: 0.00576
A30: CNS11 | B30: Real Estate & Rental/Leasing | C30: 0.016142 | D30: 0.039747
A31: CNS12 | B31: Professional, Scientific, Tech | C31: 0.212836 | D31: 0.067972
... A39: CNS20 | B39: Public Administration | C39: 0.293423 | D39: 0
B40: Total | C40: =SUM(C20:C39) | D40: =SUM(D20:D39)
A42: LODES Commute Counts and Deep Gravity Baseline Flow
B43: L_ij (workers with residence r=i, workplace s=j) | C43: 0
B44: L_ji (workers with residence r=j, workplace s=i) | C44: 154
B45: T_ij (Deep Gravity baseline flow, dummy) | C45: 1600
A47: Step 2: Bounded Perturbation Deltas Δwₑₒ = max(−wₑₒ, min(α·wₑₒ, uₑₒ−wₑₒ))
A48: Change in WFH rate for each segment, bounded by structural feasibility. Positive = more WFH; negative = less WFH.
A49: LODES | B49: Industry | C49: Less than HS | D49: HS Diploma | E49: Some College/Assoc. | F49: Bachelor's | G49: Advanced
A50: CNS01 | B50: Agriculture, Forestry, Fishing | C50: =MAX(-Parameters!C38,MIN($C$5*Parameters!C38,Parameters!C62-Parameters!C38)) | D50: =MAX(-Parameters!D38,MIN($C$5*Parameters!D38,Parameters!D62-Parameters!D38)) | E50: =MAX(-Parameters!E38,MIN($C$5*Parameters!E38,Parameters!E62-Parameters!E38)) | F50: =MAX(-Parameters!F38,MIN($C$5*Parameters!F38,Parameters!F62-Parameters!F38)) | G50: =MAX(-Parameters!G38,MIN($C$5*Parameters!G38,Parameters!G62-Parameters!G38))
A51: CNS02 | B51: Mining, Quarrying, Oil/Gas | C51: =MAX(-Parameters!C39,MIN($C$5*Parameters!C39,Parameters!C63-Parameters!C39)) | D51: =MAX(-Parameters!D39,MIN($C$5*Parameters!D39,Parameters!D63-Parameters!D39)) | E51: =MAX(-Parameters!E39,MIN($C$5*Parameters!E39,Parameters!E63-Parameters!E39)) | F51: =MAX(-Parameters!F39,MIN($C$5*Parameters!F39,Parameters!F63-Parameters!F39)) | G51: =MAX(-Parameters!G39,MIN($C$5*Parameters!G39,Parameters!G63-Parameters!G39))
A52: CNS03 | B52: Utilities | C52: =MAX(-Parameters!C40,MIN($C$5*Parameters!C40,Parameters!C64-Parameters!C40)) | D52: =MAX(-Parameters!D40,MIN($C$5*Parameters!D40,Parameters!D64-Parameters!D40)) | E52: =MAX(-Parameters!E40,MIN($C$5*Parameters!E40,Parameters!E64-Parameters!E40)) | F52: =MAX(-Parameters!F40,MIN($C$5*Parameters!F40,Parameters!F64-Parameters!F40)) | G52: =MAX(-Parameters!G40,MIN($C$5*Parameters!G40,Parameters!G64-Parameters!G40))
A53: CNS04 | B53: Construction | C53: =MAX(-Parameters!C41,MIN($C$5*Parameters!C41,Parameters!C65-Parameters!C41)) | D53: =MAX(-Parameters!D41,MIN($C$5*Parameters!D41,Parameters!D65-Parameters!D41)) | E53: =MAX(-Parameters!E41,MIN($C$5*Parameters!E41,Parameters!E65-Parameters!E41)) | F53: =MAX(-Parameters!F41,MIN($C$5*Parameters!F41,Parameters!F65-Parameters!F41)) | G53: =MAX(-Parameters!G41,MIN($C$5*Parameters!G41,Parameters!G65-Parameters!G41))
...
